Workbook

Sheet 전체요약
A1: KX 인턴십 · 1개월 예상비용 (통합)
A2: 작성일 2026-07-01 · 대상 5개 팀 (A1·A2·B1·B2·C) · 청구기간 1개월
A3: 환율 (KRW/USD) | B3: =전체내역!$B$2 -> 1550 | C3: ← 전체내역에서 관리
A5: 총 합계 | B5: =SUM(전체내역!$J$5:$J$48) -> 1572.592 | C5: =SUM(전체내역!$K$5:$K$48) -> 2437517.6 | D5: 고정 구독 = 선불·정액 / API·클라우드 = 후불·사용량
A7: ■ 팀별 요약
A8: 팀 | B8: 선불·구독 (USD) | C8: 후불·사용량 (USD) | D8: 총 USD | E8: 총 KRW | F8: 비중
A9: A1 | B9: =SUMIFS(전체내역!$J$5:$J$48,전체내역!$A$5:$A$48,A9,전체내역!$B$5:$B$48,"고정구독") -> 180 | C9: =SUMIF(전체내역!$A$5:$A$48,A9,전체내역!$J$5:$J$48)-B9 -> 197.871 | D9: =SUMIF(전체내역!$A$5:$A$48,A9,전체내역!$J$5:$J$48) -> 377.871 | E9: =SUMIF(전체내역!$A$5:$A$48,A9,전체내역!$K$5:$K$48) -> 585700.05 | F9: =D9/$B$5 -> 0.24028547
A10: A2 | B10: =SUMIFS(전체내역!$J$5:$J$48,전체내역!$A$5:$A$48,A10,전체내역!$B$5:$B$48,"고정구독") -> 180 | C10: =SUMIF(전체내역!$A$5:$A$48,A10,전체내역!$J$5:$J$48)-B10 -> 179.921 | D10: =SUMIF(전체내역!$A$5:$A$48,A10,전체내역!$J$5:$J$48) -> 359.921 | E10: =SUMIF(전체내역!$A$5:$A$48,A10,전체내역!$K$5:$K$48) -> 557877.55 | F10: =D10/$B$5 -> 0.22887119
A11: B1 | B11: =SUMIFS(전체내역!$J$5:$J$48,전체내역!$A$5:$A$48,A11,전체내역!$B$5:$B$48,"고정구독") -> 200 | C11: =SUMIF(전체내역!$A$5:$A$48,A11,전체내역!$J$5:$J$48)-B11 -> 97.275 | D11: =SUMIF(전체내역!$A$5:$A$48,A11,전체내역!$J$5:$J$48) -> 297.275 | E11: =SUMIF(전체내역!$A$5:$A$48,A11,전체내역!$K$5:$K$48) -> 460776.25 | F11: =D11/$B$5 -> 0.18903505
A12: B2 | B12: =SUMIFS(전체내역!$J$5:$J$48,전체내역!$A$5:$A$48,A12,전체내역!$B$5:$B$48,"고정구독") -> 200 | C12: =SUMIF(전체내역!$A$5:$A$48,A12,전체내역!$J$5:$J$48)-B12 -> 97.275 | D12: =SUMIF(전체내역!$A$5:$A$48,A12,전체내역!$J$5:$J$48) -> 297.275 | E12: =SUMIF(전체내역!$A$5:$A$48,A12,전체내역!$K$5:$K$48) -> 460776.25 | F12: =D12/$B$5 -> 0.18903505
A13: C | B13: =SUMIFS(전체내역!$J$5:$J$48,전체내역!$A$5:$A$48,A13,전체내역!$B$5:$B$48,"고정구독") -> 206 | C13: =SUMIF(전체내역!$A$5:$A$48,A13,전체내역!$J$5:$J$48)-B13 -> 34.25 | D13: =SUMIF(전체내역!$A$5:$A$48,A13,전체내역!$J$5:$J$48) -> 240.25 | E13: =SUMIF(전체내역!$A$5:$A$48,A13,전체내역!$K$5:$K$48) -> 372387.5 | F13: =D13/$B$5 -> 0.15277326
A14: 합계 | B14: =SUM(B9:B13) -> 966 | C14: =SUM(C9:C13) -> 606.592 | D14: =SUM(D9:D13) -> 1572.592 | E14: =SUM(E9:E13) -> 2437517.6 | F14: =D14/$B$5 -> 1
A16: ■ 카테고리별 요약
A17: 카테고리 | B17: 월 합계 (USD) | C17: 월 합계 (KRW) | D17: 비중
A18: 고정구독 | B18: =SUMIF(전체내역!$B$5:$B$48,A18,전체내역!$J$5:$J$48) -> 966 | C18: =SUMIF(전체내역!$B$5:$B$48,A18,전체내역!$K$5:$K$48) -> 1497300 | D18: =B18/$B$5 -> 0.61427249
A19: 클라우드/배포 | B19: =SUMIF(전체내역!$B$5:$B$48,A19,전체내역!$J$5:$J$48) -> 256 | C19: =SUMIF(전체내역!$B$5:$B$48,A19,전체내역!$K$5:$K$48) -> 396800 | D19: =B19/$B$5 -> 0.16278857
A20: LLM API | B20: =SUMIF(전체내역!$B$5:$B$48,A20,전체내역!$J$5:$J$48) -> 55.13 | C20: =SUMIF(전체내역!$B$5:$B$48,A20,전체내역!$K$5:$K$48) -> 85451.5 | D20: =B20/$B$5 -> 0.035056773
A21: 이미지 생성 | B21: =SUMIF(전체내역!$B$5:$B$48,A21,전체내역!$J$5:$J$48) -> 141.95 | C21: =SUMIF(전체내역!$B$5:$B$48,A21,전체내역!$K$5:$K$48) -> 220022.5 | D21: =B21/$B$5 -> 0.090264989
A22: 영상 생성 | B22: =SUMIF(전체내역!$B$5:$B$48,A22,전체내역!$J$5:$J$48) -> 139.262 | C22: =SUMIF(전체내역!$B$5:$B$48,A22,전체내역!$K$5:$K$48) -> 215856.1 | D22: =B22/$B$5 -> 0.088555709
A23: STT/자막 | B23: =SUMIF(전체내역!$B$5:$B$48,A23,전체내역!$J$5:$J$48) -> 14.25 | C23: =SUMIF(전체내역!$B$5:$B$48,A23,전체내역!$K$5:$K$48) -> 22087.5 | D23: =B23/$B$5 -> 0.009061473
A24: 합계 | B24: =SUM(B18:B23) -> 1572.592 | C24: =SUM(C18:C23) -> 2437517.6 | D24: =B24/$B$5 -> 1
A26: ★ 항목별 통합 내역 (전 팀 합산)
A27: 통합 항목 | B27: 조달유형 / 과금 | C27: 규모 · 사용 팀 | D27: 월 합계 (USD) | E27: 월 합계 (KRW) | F27: 용도·목적
A28: Claude Team | B28: 좌석형 선불·정액 | C28: 20석 (팀당 4석, PM 제외) | D28: =SUMIF(전체내역!$C$5:$C$48,A28,전체내역!$J$5:$J$48) -> 600 | E28: =SUMIF(전체내역!$C$5:$C$48,A28,전체내역!$K$5:$K$48) -> 930000 | F28: AI 코드 제안·오류 수정 실시간 지원 · 문서·에이전트 개발
A29: Figma Professional | B29: 좌석형 선불·정액 | C29: 13석 (FE+UX/UI, C팀 PM 포함) | D29: =SUMIF(전체내역!$C$5:$C$48,A29,전체내역!$J$5:$J$48) -> 260 | E29: =SUMIF(전체내역!$C$5:$C$48,A29,전체내역!$K$5:$K$48) -> 403000 | F29: 서비스 화면 설계 및 팀원 실시간 공동 편집·공유
A30: Vercel Pro | B30: 팀별 인스턴스 선불·정액 | C30: 5개 (팀당 1) | D30: =SUMIF(전체내역!$C$5:$C$48,A30,전체내역!$J$5:$J$48) -> 100 | E30: =SUMIF(전체내역!$C$5:$C$48,A30,전체내역!$K$5:$K$48) -> 155000 | F30: 프론트엔드 자동 배포 및 데모 운영 환경
A31: ElevenLabs | B31: 좌석형(키 공유) 선불·정액 | C31: 1개 (C팀) | D31: =SUMIF(전체내역!$C$5:$C$48,A31,전체내역!$J$5:$J$48) -> 6 | E31: =SUMIF(전체내역!$C$5:$C$48,A31,전체내역!$K$5:$K$48) -> 9300 | F31: 영상 장면에 맞는 효과음 생성 API
A32: AWS EC2 | B32: 팀별 인스턴스 후불·사용량 | C32: 5개 (팀당 1) | D32: =SUMIF(전체내역!$C$5:$C$48,A32,전체내역!$J$5:$J$48) -> 256 | E32: =SUMIF(전체내역!$C$5:$C$48,A32,전체내역!$K$5:$K$48) -> 396800 | F32: 백엔드 서버 운영 및 파일 저장
A33: Claude Sonnet API | B33: API 키형 후불·사용량 | C33: A1·A2·B1·B2 | D33: =SUMIF(전체내역!$C$5:$C$48,A33,전체내역!$J$5:$J$48) -> 25.8 | E33: =SUMIF(전체내역!$C$5:$C$48,A33,전체내역!$K$5:$K$48) -> 39990 | F33: 프롬프트 해석·역프롬프트 및 영상 프롬프트 생성
A34: GPT-4.1 vision | B34: API 키형 후불·사용량 | C34: A1·B1·B2 | D34: =SUMIF(전체내역!$C$5:$C$48,A34,전체내역!$J$5:$J$48) -> 29.33 | E34: =SUMIF(전체내역!$C$5:$C$48,A34,전체내역!$K$5:$K$48) -> 45461.5 | F34: 이미지 분석 및 컷 생성 역프롬프트
A35: GPT Image 2 | B35: API 키형 후불·사용량 | C35: A1·A2 | D35: =SUMIF(전체내역!$C$5:$C$48,A35,전체내역!$J$5:$J$48) -> 24.95 | E35: =SUMIF(전체내역!$C$5:$C$48,A35,전체내역!$K$5:$K$48) -> 38672.5 | F35: 텍스트 설명 기반 이미지 생성
A36: Gemini 3.5 flash image | B36: API 키형 후불·사용량 | C36: B1·B2 | D36: =SUMIF(전체내역!$C$5:$C$48,A36,전체내역!$J$5:$J$48) -> 117 | E36: =SUMIF(전체내역!$C$5:$C$48,A36,전체내역!$K$5:$K$48) -> 181350 | F36: 이미지 생성
A37: fal.ai (Kling·Seedance) | B37: API 키형 후불·사용량 | C37: A1·A2 (한도 $100) | D37: =SUMIF(전체내역!$C$5:$C$48,A37,전체내역!$J$5:$J$48) -> 139.262 | E37: =SUMIF(전체내역!$C$5:$C$48,A37,전체내역!$K$5:$K$48) -> 215856.1 | F37: 스토리보드 기반 영상 클립 생성
A38: OpenAI Whisper | B38: API 키형 후불·사용량 | C38: C팀 | D38: =SUMIF(전체내역!$C$5:$C$48,A38,전체내역!$J$5:$J$48) -> 9 | E38: =SUMIF(전체내역!$C$5:$C$48,A38,전체내역!$K$5:$K$48) -> 13950 | F38: 기본 음성 인식(STT) 및 자동 자막
A39: AssemblyAI | B39: API 키형 후불·사용량 | C39: C팀 | D39: =SUMIF(전체내역!$C$5:$C$48,A39,전체내역!$J$5:$J$48) -> 5.25 | E39: =SUMIF(전체내역!$C$5:$C$48,A39,전체내역!$K$5:$K$48) -> 8137.5 | F39: 정밀 자막 생성 및 STT 성능 비교
A40: 합계 | D40: =SUM(D28:D39) -> 1572.592 | E40: =SUM(E28:E39) -> 2437517.6

Sheet 전체내역
A1: 전체내역 (정규화 마스터) — 필터·집계용
A2: 환율(KRW/USD) | B2: 1550 | C2: ← 제출 시점 환율로 갱신 (전 시트 KRW 자동 반영)
A4: 팀 | B4: 카테고리 | C4: 통합항목 | D4: 세부항목 | E4: 조달유형 | F4: 과금 | G4: 단가(USD) | H4: 수량 | I4: 단위 | J4: 합계(USD) | K4: 합계(KRW) | L4: 용도·목적 | M4: 산출근거
A5: A1 | B5: 고정구독 | C5: Claude Team | D5: Claude Team | E5: 좌석형 | F5: 선불 | G5: 30 | H5: 4 | I5: 석 | J5: =G5*H5 -> 120 | K5: =J5*전체내역!$B$2 -> 186000 | L5: AI 코드 제안·오류 수정 실시간 지원, 문서·에이전트 개발 | M5: PM 제외 4석
A6: A1 | B6: 고정구독 | C6: Figma Professional | D6: Figma Professional | E6: 좌석형 | F6: 선불 | G6: 20 | H6: 2 | I6: 석 | J6: =G6*H6 -> 40 | K6: =J6*전체내역!$B$2 -> 62000 | L6: FE 1 + UX/UI 1, 실시간 공동 디자인
A7: A1 | B7: 고정구독 | C7: Vercel Pro | D7: Vercel Pro | E7: 팀별 인스턴스 | F7: 선불 | G7: 20 | H7: 1 | I7: 개 | J7: =G7*H7 -> 20 | K7: =J7*전체내역!$B$2 -> 31000 | L7: 코드 업로드 시 자동 웹 배포
A8: A1 | B8: 클라우드/배포 | C8: AWS EC2 | D8: AWS EC2 (예비 예산) | E8: 팀별 인스턴스 | F8: 후불 | G8: 100 | H8: 1 | I8: 개 | J8: =G8*H8 -> 100 | K8: =J8*전체내역!$B$2 -> 155000 | L8: Free Tier 만료 대비 예비·백엔드 운영 | M8: 상한 예비, 실사용 정산
A9: A1 | B9: LLM API | C9: Claude Sonnet API | D9: Claude Sonnet — 프롬프트 보조 | E9: API 키형 | F9: 후불 | G9: 0.015 | H9: 350 | I9: 호출 | J9: =G9*H9 -> 5.25 | K9: =J9*전체내역!$B$2 -> 8137.5 | L9: 프롬프트 해석·역프롬프트 생성 | M9: 2000/600토큰, $3/$15·1M
A10: A1 | B10: LLM API | C10: GPT-4.1 vision | D10: GPT-4.1 vision | E10: API 키형 | F10: 후불 | G10: 0.0088 | H10: 350 | I10: 호출 | J10: =G10*H10 -> 3.08 | K10: =J10*전체내역!$B$2 -> 4774 | L10: 이미지 분석·역프롬프트 | M10: 2000/600토큰, $2/$8·1M
A11: A1 | B11: 이미지 생성 | C11: GPT Image 2 | D11: GPT Image 2 Low | E11: API 키형 | F11: 후불 | G11: 0.006 | H11: 150 | I11: 장 | J11: =G11*H11 -> 0.9 | K11: =J11*전체내역!$B$2 -> 1395 | L11: 빠른 반복 테스트·기능 검증
A12: A1 | B12: 이미지 생성 | C12: GPT Image 2 | D12: GPT Image 2 Medium | E12: API 키형 | F12: 후불 | G12: 0.053 | H12: 80 | I12: 장 | J12: =G12*H12 -> 4.24 | K12: =J12*전체내역!$B$2 -> 6572 | L12: 품질 검증·기능 테스트
A13: A1 | B13: 이미지 생성 | C13: GPT Image 2 | D13: GPT Image 2 High | E13: API 키형 | F13: 후불 | G13: 0.211 | H13: 70 | I13: 장 | J13: =G13*H13 -> 14.77 | K13: =J13*전체내역!$B$2 -> 22893.5 | L13: 최종 시연·발표용 고품질
A14: A1 | B14: 영상 생성 | C14: fal.ai (Kling·Seedance) | D14: fal.ai Kling — 개발 테스트(5초) | E14: API 키형 | F14: 후불 | G14: 0.11 | H14: 40 | I14: 초 | J14: =G14*H14 -> 4.4 | K14: =J14*전체내역!$B$2 -> 6820 | L14: 저비용 반복 테스트·오류 조기 발견 | M14: 8세트×5초
A15: A1 | B15: 영상 생성 | C15: fal.ai (Kling·Seedance) | D15: fal.ai Seedance — 2주차 품질(5초) | E15: API 키형 | F15: 후불 | G15: 0.3034 | H15: 50 | I15: 초 | J15: =G15*H15 -> 15.17 | K15: =J15*전체내역!$B$2 -> 23513.5 | L15: 실제 품질 사전 확인 | M15: 10세트×5초
A16: A1 | B16: 영상 생성 | C16: fal.ai (Kling·Seedance) | D16: fal.ai Seedance — 3주차 품질(10초) | E16: API 키형 | F16: 후불 | G16: 0.3034 | H16: 60 | I16: 초 | J16: =G16*H16 -> 18.204 | K16: =J16*전체내역!$B$2 -> 28216.2 | L16: 길이·품질 옵션 비교 | M16: 6세트×10초
A17: A1 | B17: 영상 생성 | C17: fal.ai (Kling·Seedance) | D17: fal.ai Seedance — 4주차 최종(15초) | E17: API 키형 | F17: 후불 | G17: 0.3034 | H17: 105 | I17: 초 | J17: =G17*H17 -> 31.857 | K17: =J17*전체내역!$B$2 -> 49378.35 | L17: 발표·시연용 최종 출력 | M17: 7세트×15초
A18: A2 | B18: 고정구독 | C18: Claude Team | D18: Claude Team | E18: 좌석형 | F18: 선불 | G18: 30 | H18: 4 | I18: 석 | J18: =G18*H18 -> 120 | K18: =J18*전체내역!$B$2 -> 186000 | L18: AI 코드 지원·문서·에이전트 개발 | M18: PM 제외 4석
A19: A2 | B19: 고정구독 | C19: Figma Professional | D19: Figma Professional | E19: 좌석형 | F19: 선불 | G19: 20 | H19: 2 | I19: 석 | J19: =G19*H19 -> 40 | K19: =J19*전체내역!$B$2 -> 62000 | L19: FE 1 + UX/UI 1
A20: A2 | B20: 고정구독 | C20: Vercel Pro | D20: Vercel Pro | E20: 팀별 인스턴스 | F20: 선불 | G20: 20 | H20: 1 | I20: 개 | J20: =G20*H20 -> 20 | K20: =J20*전체내역!$B$2 -> 31000 | L20: 프론트 자동 배포
A21: A2 | B21: 클라우드/배포 | C21: AWS EC2 | D21: AWS EC2 (예비 예산) | E21: 팀별 인스턴스 | F21: 후불 | G21: 100 | H21: 1 | I21: 개 | J21: =G21*H21 -> 100 | K21: =J21*전체내역!$B$2 -> 155000 | L21: Free Tier 만료 대비 예비·백엔드 운영 | M21: 상한 예비, 실사용 정산
A22: A2 | B22: LLM API | C22: Claude Sonnet API | D22: Claude Sonnet — 프롬프트 보조 | E22: API 키형 | F22: 후불 | G22: 0.015 | H22: 350 | I22: 호출 | J22: =G22*H22 -> 5.25 | K22: =J22*전체내역!$B$2 -> 8137.5 | L22: 프롬프트 해석·역프롬프트 | M22: 2000/600토큰
A23: A2 | B23: 이미지 생성 | C23: GPT Image 2 | D23: GPT Image 2 — 단일 이미지 | E23: API 키형 | F23: 후불 | G23: 0.042 | H23: 120 | I23: 장 | J23: =G23*H23 -> 5.04 | K23: =J23*전체내역!$B$2 -> 7812 | L23: 이미지 생성 테스트·데모
A24: A2 | B24: 영상 생성 | C24: fal.ai (Kling·Seedance) | D24: fal.ai Kling — 개발 테스트(5초) | E24: API 키형 | F24: 후불 | G24: 0.11 | H24: 40 | I24: 초 | J24: =G24*H24 -> 4.4 | K24: =J24*전체내역!$B$2 -> 6820 | L24: 반복 테스트 | M24: 8세트×5초
A25: A2 | B25: 영상 생성 | C25: fal.ai (Kling·Seedance) | D25: fal.ai Seedance — 2주차 품질(5초) | E25: API 키형 | F25: 후불 | G25: 0.3034 | H25: 50 | I25: 초 | J25: =G25*H25 -> 15.17 | K25: =J25*전체내역!$B$2 -> 23513.5 | L25: 품질 사전 확인 | M25: 10세트×5초
A26: A2 | B26: 영상 생성 | C26: fal.ai (Kling·Seedance) | D26: fal.ai Seedance — 3주차 품질(10초) | E26: API 키형 | F26: 후불 | G26: 0.3034 | H26: 60 | I26: 초 | J26: =G26*H26 -> 18.204 | K26: =J26*전체내역!$B$2 -> 28216.2 | L26: 옵션 비교 | M26: 6세트×10초
A27: A2 | B27: 영상 생성 | C27: fal.ai (Kling·Seedance) | D27: fal.ai Seedance — 4주차 최종(15초) | E27: API 키형 | F27: 후불 | G27: 0.3034 | H27: 105 | I27: 초 | J27: =G27*H27 -> 31.857 | K27: =J27*전체내역!$B$2 -> 49378.35 | L27: 최종 출력 | M27: 7세트×15초
A28: B1 | B28: 고정구독 | C28: Claude Team | D28: Claude Team | E28: 좌석형 | F28: 선불 | G28: 30 | H28: 4 | I28: 석 | J28: =G28*H28 -> 120 | K28: =J28*전체내역!$B$2 -> 186000 | L28: AI 코드 지원·문서·에이전트 개발 | M28: 개발 인원 4명
A29: B1 | B29: 고정구독 | C29: Figma Professional | D29: Figma Professional | E29: 좌석형 | F29: 선불 | G29: 20 | H29: 3 | I29: 석 | J29: =G29*H29 -> 60 | K29: =J29*전체내역!$B$2 -> 93000 | L29: FE 2 + UX/UI 1
A30: B1 | B30: 고정구독 | C30: Vercel Pro | D30: Vercel Pro | E30: 팀별 인스턴스 | F30: 선불 | G30: 20 | H30: 1 | I30: 개 | J30: =G30*H30 -> 20 | K30: =J30*전체내역!$B$2 -> 31000 | L30: 프론트 배포
A31: B1 | B31: 클라우드/배포 | C31: AWS EC2 | D31: AWS EC2 (후불) | E31: 팀별 인스턴스 | F31: 후불 | G31: 18 | H31: 1 | I31: 개 | J31: =G31*H31 -> 18 | K31: =J31*전체내역!$B$2 -> 27900 | L31: 백엔드 배포
A32: B1 | B32: LLM API | C32: Claude Sonnet API | D32: claude-sonnet API | E32: API 키형 | F32: 후불 | G32: 0.0255 | H32: 300 | I32: 호출 | J32: =G32*H32 -> 7.65 | K32: =J32*전체내역!$B$2 -> 11857.5 | L32: 영상 프롬프트 생성 | M32: 2500/1200토큰
A33: B1 | B33: LLM API | C33: GPT-4.1 vision | D33: GPT-4.1 vision (상위) | E33: API 키형 | F33: 후불 | G33: 0.00875 | H33: 1500 | I33: 호출 | J33: =G33*H33 -> 13.125 | K33: =J33*전체내역!$B$2 -> 20343.75 | L33: 컷 생성·이미지 분석 | M33: 1500/500토큰
A34: B1 | B34: 이미지 생성 | C34: Gemini 3.5 flash image | D34: gemini-3.5-flash-image | E34: API 키형 | F34: 후불 | G34: 0.039 | H34: 1500 | I34: 장 | J34: =G34*H34 -> 58.5 | K34: =J34*전체내역!$B$2 -> 90675 | L34: 이미지 생성
A35: B2 | B35: 고정구독 | C35: Claude Team | D35: Claude Team | E35: 좌석형 | F35: 선불 | G35: 30 | H35: 4 | I35: 석 | J35: =G35*H35 -> 120 | K35: =J35*전체내역!$B$2 -> 186000 | L35: AI 코드 지원·문서·에이전트 개발 | M35: 개발 인원 4명
A36: B2 | B36: 고정구독 | C36: Figma Professional | D36: Figma Professional | E36: 좌석형 | F36: 선불 | G36: 20 | H36: 3 | I36: 석 | J36: =G36*H36 -> 60 | K36: =J36*전체내역!$B$2 -> 93000 | L36: FE 2 + UX/UI 1
A37: B2 | B37: 고정구독 | C37: Vercel Pro | D37: Vercel Pro | E37: 팀별 인스턴스 | F37: 선불 | G37: 20 | H37: 1 | I37: 개 | J37: =G37*H37 -> 20 | K37: =J37*전체내역!$B$2 -> 31000 | L37: 프론트 배포
A38: B2 | B38: 클라우드/배포 | C38: AWS EC2 | D38: AWS EC2 (후불) | E38: 팀별 인스턴스 | F38: 후불 | G38: 18 | H38: 1 | I38: 개 | J38: =G38*H38 -> 18 | K38: =J38*전체내역!$B$2 -> 27900 | L38: 백엔드 배포
A39: B2 | B39: LLM API | C39: Claude Sonnet API | D39: claude-sonnet API | E39: API 키형 | F39: 후불 | G39: 0.0255 | H39: 300 | I39: 호출 | J39: =G39*H39 -> 7.65 | K39: =J39*전체내역!$B$2 -> 11857.5 | L39: 영상 프롬프트 생성 | M39: 2500/1200토큰
A40: B2 | B40: LLM API | C40: GPT-4.1 vision | D40: GPT-4.1 vision (상위) | E40: API 키형 | F40: 후불 | G40: 0.00875 | H40: 1500 | I40: 호출 | J40: =G40*H40 -> 13.125 | K40: =J40*전체내역!$B$2 -> 20343.75 | L40: 컷 생성·이미지 분석 | M40: 1500/500토큰
A41: B2 | B41: 이미지 생성 | C41: Gemini 3.5 flash image | D41: gemini-3.5-flash-image | E41: API 키형 | F41: 후불 | G41: 0.039 | H41: 1500 | I41: 장 | J41: =G41*H41 -> 58.5 | K41: =J41*전체내역!$B$2 -> 90675 | L41: 이미지 생성
...

Sheet A1
A1: KX_A1 · 1개월 예상 비용 (청구용)
A2: 환율 1,550 KRW/USD · 청구기간 1개월 · 금액은 전체내역 마스터와 연동
A4: 항목 | B4: 단가(USD) | C4: 수량 | D4: 단위 | E4: 합계(USD) | F4: 합계(KRW) | G4: 조달유형 | H4: 용도·목적
A5: 고정구독
A6: Claude Team | B6: 30 | C6: 4 | D6: 석 | E6: =SUMIFS(전체내역!$J$5:$J$48,전체내역!$A$5:$A$48,"A1",전체내역!$D$5:$D$48,A6) -> 120 | F6: =E6*전체내역!$B$2 -> 186000 | G6: 좌석형 | H6: AI 코드 제안·오류 수정 실시간 지원, 문서·에이전트 개발
A7: Figma Professional | B7: 20 | C7: 2 | D7: 석 | E7: =SUMIFS(전체내역!$J$5:$J$48,전체내역!$A$5:$A$48,"A1",전체내역!$D$5:$D$48,A7) -> 40 | F7: =E7*전체내역!$B$2 -> 62000 | G7: 좌석형 | H7: FE 1 + UX/UI 1, 실시간 공동 디자인
A8: Vercel Pro | B8: 20 | C8: 1 | D8: 개 | E8: =SUMIFS(전체내역!$J$5:$J$48,전체내역!$A$5:$A$48,"A1",전체내역!$D$5:$D$48,A8) -> 20 | F8: =E8*전체내역!$B$2 -> 31000 | G8: 팀별 인스턴스 | H8: 코드 업로드 시 자동 웹 배포
A9: 고정구독 소계 | E9: =SUM(E6:E8) -> 180 | F9: =SUM(F6:F8) -> 279000
A10: 클라우드/배포
A11: AWS EC2 (예비 예산) | B11: 100 | C11: 1 | D11: 개 | E11: =SUMIFS(전체내역!$J$5:$J$48,전체내역!$A$5:$A$48,"A1",전체내역!$D$5:$D$48,A11) -> 100 | F11: =E11*전체내역!$B$2 -> 155000 | G11: 팀별 인스턴스 | H11: Free Tier 만료 대비 예비·백엔드 운영
A12: 클라우드/배포 소계 | E12: =SUM(E11:E11) -> 100 | F12: =SUM(F11:F11) -> 155000
A13: LLM API
A14: Claude Sonnet — 프롬프트 보조 | B14: 0.015 | C14: 350 | D14: 호출 | E14: =SUMIFS(전체내역!$J$5:$J$48,전체내역!$A$5:$A$48,"A1",전체내역!$D$5:$D$48,A14) -> 5.25 | F14: =E14*전체내역!$B$2 -> 8137.5 | G14: API 키형 | H14: 프롬프트 해석·역프롬프트 생성
A15: GPT-4.1 vision | B15: 0.0088 | C15: 350 | D15: 호출 | E15: =SUMIFS(전체내역!$J$5:$J$48,전체내역!$A$5:$A$48,"A1",전체내역!$D$5:$D$48,A15) -> 3.08 | F15: =E15*전체내역!$B$2 -> 4774 | G15: API 키형 | H15: 이미지 분석·역프롬프트
A16: LLM API 소계 | E16: =SUM(E14:E15) -> 8.33 | F16: =SUM(F14:F15) -> 12911.5
A17: 이미지 생성
A18: GPT Image 2 Low | B18: 0.006 | C18: 150 | D18: 장 | E18: =SUMIFS(전체내역!$J$5:$J$48,전체내역!$A$5:$A$48,"A1",전체내역!$D$5:$D$48,A18) -> 0.9 | F18: =E18*전체내역!$B$2 -> 1395 | G18: API 키형 | H18: 빠른 반복 테스트·기능 검증
A19: GPT Image 2 Medium | B19: 0.053 | C19: 80 | D19: 장 | E19: =SUMIFS(전체내역!$J$5:$J$48,전체내역!$A$5:$A$48,"A1",전체내역!$D$5:$D$48,A19) -> 4.24 | F19: =E19*전체내역!$B$2 -> 6572 | G19: API 키형 | H19: 품질 검증·기능 테스트
A20: GPT Image 2 High | B20: 0.211 | C20: 70 | D20: 장 | E20: =SUMIFS(전체내역!$J$5:$J$48,전체내역!$A$5:$A$48,"A1",전체내역!$D$5:$D$48,A20) -> 14.77 | F20: =E20*전체내역!$B$2 -> 22893.5 | G20: API 키형 | H20: 최종 시연·발표용 고품질
A21: 이미지 생성 소계 | E21: =SUM(E18:E20) -> 19.91 | F21: =SUM(F18:F20) -> 30860.5
A22: 영상 생성
A23: fal.ai Kling — 개발 테스트(5초) | B23: 0.11 | C23: 40 | D23: 초 | E23: =SUMIFS(전체내역!$J$5:$J$48,전체내역!$A$5:$A$48,"A1",전체내역!$D$5:$D$48,A23) -> 4.4 | F23: =E23*전체내역!$B$2 -> 6820 | G23: API 키형 | H23: 저비용 반복 테스트·오류 조기 발견
A24: fal.ai Seedance — 2주차 품질(5초) | B24: 0.3034 | C24: 50 | D24: 초 | E24: =SUMIFS(전체내역!$J$5:$J$48,전체내역!$A$5:$A$48,"A1",전체내역!$D$5:$D$48,A24) -> 15.17 | F24: =E24*전체내역!$B$2 -> 23513.5 | G24: API 키형 | H24: 실제 품질 사전 확인
A25: fal.ai Seedance — 3주차 품질(10초) | B25: 0.3034 | C25: 60 | D25: 초 | E25: =SUMIFS(전체내역!$J$5:$J$48,전체내역!$A$5:$A$48,"A1",전체내역!$D$5:$D$48,A25) -> 18.204 | F25: =E25*전체내역!$B$2 -> 28216.2 | G25: API 키형 | H25: 길이·품질 옵션 비교
A26: fal.ai Seedance — 4주차 최종(15초) | B26: 0.3034 | C26: 105 | D26: 초 | E26: =SUMIFS(전체내역!$J$5:$J$48,전체내역!$A$5:$A$48,"A1",전체내역!$D$5:$D$48,A26) -> 31.857 | F26: =E26*전체내역!$B$2 -> 49378.35 | G26: API 키형 | H26: 발표·시연용 최종 출력
A27: 영상 생성 소계 | E27: =SUM(E23:E26) -> 69.631 | F27: =SUM(F23:F26) -> 107928.05
A28: ★ 총 합계 | E28: =SUMIF(전체내역!$A$5:$A$48,"A1",전체내역!$J$5:$J$48) -> 377.871 | F28: =SUMIF(전체내역!$A$5:$A$48,"A1",전체내역!$K$5:$K$48) -> 585700.05

Sheet A2
A1: KX_A2 · 1개월 예상 비용 (청구용)
A2: 환율 1,550 KRW/USD · 청구기간 1개월 · 금액은 전체내역 마스터와 연동
A4: 항목 | B4: 단가(USD) | C4: 수량 | D4: 단위 | E4: 합계(USD) | F4: 합계(KRW) | G4: 조달유형 | H4: 용도·목적
A5: 고정구독
A6: Claude Team | B6: 30 | C6: 4 | D6: 석 | E6: =SUMIFS(전체내역!$J$5:$J$48,전체내역!$A$5:$A$48,"A2",전체내역!$D$5:$D$48,A6) -> 120 | F6: =E6*전체내역!$B$2 -> 186000 | G6: 좌석형 | H6: AI 코드 지원·문서·에이전트 개발
A7: Figma Professional | B7: 20 | C7: 2 | D7: 석 | E7: =SUMIFS(전체내역!$J$5:$J$48,전체내역!$A$5:$A$48,"A2",전체내역!$D$5:$D$48,A7) -> 40 | F7: =E7*전체내역!$B$2 -> 62000 | G7: 좌석형 | H7: FE 1 + UX/UI 1
A8: Vercel Pro | B8: 20 | C8: 1 | D8: 개 | E8: =SUMIFS(전체내역!$J$5:$J$48,전체내역!$A$5:$A$48,"A2",전체내역!$D$5:$D$48,A8) -> 20 | F8: =E8*전체내역!$B$2 -> 31000 | G8: 팀별 인스턴스 | H8: 프론트 자동 배포
A9: 고정구독 소계 | E9: =SUM(E6:E8) -> 180 | F9: =SUM(F6:F8) -> 279000
A10: 클라우드/배포
A11: AWS EC2 (예비 예산) | B11: 100 | C11: 1 | D11: 개 | E11: =SUMIFS(전체내역!$J$5:$J$48,전체내역!$A$5:$A$48,"A2",전체내역!$D$5:$D$48,A11) -> 100 | F11: =E11*전체내역!$B$2 -> 155000 | G11: 팀별 인스턴스 | H11: Free Tier 만료 대비 예비·백엔드 운영
A12: 클라우드/배포 소계 | E12: =SUM(E11:E11) -> 100 | F12: =SUM(F11:F11) -> 155000
A13: LLM API
A14: Claude Sonnet — 프롬프트 보조 | B14: 0.015 | C14: 350 | D14: 호출 | E14: =SUMIFS(전체내역!$J$5:$J$48,전체내역!$A$5:$A$48,"A2",전체내역!$D$5:$D$48,A14) -> 5.25 | F14: =E14*전체내역!$B$2 -> 8137.5 | G14: API 키형 | H14: 프롬프트 해석·역프롬프트
A15: LLM API 소계 | E15: =SUM(E14:E14) -> 5.25 | F15: =SUM(F14:F14) -> 8137.5
A16: 이미지 생성
A17: GPT Image 2 — 단일 이미지 | B17: 0.042 | C17: 120 | D17: 장 | E17: =SUMIFS(전체내역!$J$5:$J$48,전체내역!$A$5:$A$48,"A2",전체내역!$D$5:$D$48,A17) -> 5.04 | F17: =E17*전체내역!$B$2 -> 7812 | G17: API 키형 | H17: 이미지 생성 테스트·데모
A18: 이미지 생성 소계 | E18: =SUM(E17:E17) -> 5.04 | F18: =SUM(F17:F17) -> 7812
A19: 영상 생성
A20: fal.ai Kling — 개발 테스트(5초) | B20: 0.11 | C20: 40 | D20: 초 | E20: =SUMIFS(전체내역!$J$5:$J$48,전체내역!$A$5:$A$48,"A2",전체내역!$D$5:$D$48,A20) -> 4.4 | F20: =E20*전체내역!$B$2 -> 6820 | G20: API 키형 | H20: 반복 테스트
A21: fal.ai Seedance — 2주차 품질(5초) | B21: 0.3034 | C21: 50 | D21: 초 | E21: =SUMIFS(전체내역!$J$5:$J$48,전체내역!$A$5:$A$48,"A2",전체내역!$D$5:$D$48,A21) -> 15.17 | F21: =E21*전체내역!$B$2 -> 23513.5 | G21: API 키형 | H21: 품질 사전 확인
A22: fal.ai Seedance — 3주차 품질(10초) | B22: 0.3034 | C22: 60 | D22: 초 | E22: =SUMIFS(전체내역!$J$5:$J$48,전체내역!$A$5:$A$48,"A2",전체내역!$D$5:$D$48,A22) -> 18.204 | F22: =E22*전체내역!$B$2 -> 28216.2 | G22: API 키형 | H22: 옵션 비교
A23: fal.ai Seedance — 4주차 최종(15초) | B23: 0.3034 | C23: 105 | D23: 초 | E23: =SUMIFS(전체내역!$J$5:$J$48,전체내역!$A$5:$A$48,"A2",전체내역!$D$5:$D$48,A23) -> 31.857 | F23: =E23*전체내역!$B$2 -> 49378.35 | G23: API 키형 | H23: 최종 출력
A24: 영상 생성 소계 | E24: =SUM(E20:E23) -> 69.631 | F24: =SUM(F20:F23) -> 107928.05
A25: ★ 총 합계 | E25: =SUMIF(전체내역!$A$5:$A$48,"A2",전체내역!$J$5:$J$48) -> 359.921 | F25: =SUMIF(전체내역!$A$5:$A$48,"A2",전체내역!$K$5:$K$48) -> 557877.55

Sheet B1
A1: KX_B1 · 1개월 예상 비용 (청구용)
A2: 환율 1,550 KRW/USD · 청구기간 1개월 · 금액은 전체내역 마스터와 연동
A4: 항목 | B4: 단가(USD) | C4: 수량 | D4: 단위 | E4: 합계(USD) | F4: 합계(KRW) | G4: 조달유형 | H4: 용도·목적
A5: 고정구독
A6: Claude Team | B6: 30 | C6: 4 | D6: 석 | E6: =SUMIFS(전체내역!$J$5:$J$48,전체내역!$A$5:$A$48,"B1",전체내역!$D$5:$D$48,A6) -> 120 | F6: =E6*전체내역!$B$2 -> 186000 | G6: 좌석형 | H6: AI 코드 지원·문서·에이전트 개발
A7: Figma Professional | B7: 20 | C7: 3 | D7: 석 | E7: =SUMIFS(전체내역!$J$5:$J$48,전체내역!$A$5:$A$48,"B1",전체내역!$D$5:$D$48,A7) -> 60 | F7: =E7*전체내역!$B$2 -> 93000 | G7: 좌석형 | H7: FE 2 + UX/UI 1
A8: Vercel Pro | B8: 20 | C8: 1 | D8: 개 | E8: =SUMIFS(전체내역!$J$5:$J$48,전체내역!$A$5:$A$48,"B1",전체내역!$D$5:$D$48,A8) -> 20 | F8: =E8*전체내역!$B$2 -> 31000 | G8: 팀별 인스턴스 | H8: 프론트 배포
A9: 고정구독 소계 | E9: =SUM(E6:E8) -> 200 | F9: =SUM(F6:F8) -> 310000
A10: 클라우드/배포
A11: AWS EC2 (후불) | B11: 18 | C11: 1 | D11: 개 | E11: =SUMIFS(전체내역!$J$5:$J$48,전체내역!$A$5:$A$48,"B1",전체내역!$D$5:$D$48,A11) -> 18 | F11: =E11*전체내역!$B$2 -> 27900 | G11: 팀별 인스턴스 | H11: 백엔드 배포
A12: 클라우드/배포 소계 | E12: =SUM(E11:E11) -> 18 | F12: =SUM(F11:F11) -> 27900
A13: LLM API
A14: claude-sonnet API | B14: 0.0255 | C14: 300 | D14: 호출 | E14: =SUMIFS(전체내역!$J$5:$J$48,전체내역!$A$5:$A$48,"B1",전체내역!$D$5:$D$48,A14) -> 7.65 | F14: =E14*전체내역!$B$2 -> 11857.5 | G14: API 키형 | H14: 영상 프롬프트 생성
A15: GPT-4.1 vision (상위) | B15: 0.00875 | C15: 1500 | D15: 호출 | E15: =SUMIFS(전체내역!$J$5:$J$48,전체내역!$A$5:$A$48,"B1",전체내역!$D$5:$D$48,A15) -> 13.125 | F15: =E15*전체내역!$B$2 -> 20343.75 | G15: API 키형 | H15: 컷 생성·이미지 분석
A16: LLM API 소계 | E16: =SUM(E14:E15) -> 20.775 | F16: =SUM(F14:F15) -> 32201.25
A17: 이미지 생성
A18: gemini-3.5-flash-image | B18: 0.039 | C18: 1500 | D18: 장 | E18: =SUMIFS(전체내역!$J$5:$J$48,전체내역!$A$5:$A$48,"B1",전체내역!$D$5:$D$48,A18) -> 58.5 | F18: =E18*전체내역!$B$2 -> 90675 | G18: API 키형 | H18: 이미지 생성
A19: 이미지 생성 소계 | E19: =SUM(E18:E18) -> 58.5 | F19: =SUM(F18:F18) -> 90675
A20: ★ 총 합계 | E20: =SUMIF(전체내역!$A$5:$A$48,"B1",전체내역!$J$5:$J$48) -> 297.275 | F20: =SUMIF(전체내역!$A$5:$A$48,"B1",전체내역!$K$5:$K$48) -> 460776.25

Sheet B2
A1: KX_B2 · 1개월 예상 비용 (청구용)
A2: 환율 1,550 KRW/USD · 청구기간 1개월 · 금액은 전체내역 마스터와 연동
A4: 항목 | B4: 단가(USD) | C4: 수량 | D4: 단위 | E4: 합계(USD) | F4: 합계(KRW) | G4: 조달유형 | H4: 용도·목적
A5: 고정구독
A6: Claude Team | B6: 30 | C6: 4 | D6: 석 | E6: =SUMIFS(전체내역!$J$5:$J$48,전체내역!$A$5:$A$48,"B2",전체내역!$D$5:$D$48,A6) -> 120 | F6: =E6*전체내역!$B$2 -> 186000 | G6: 좌석형 | H6: AI 코드 지원·문서·에이전트 개발
A7: Figma Professional | B7: 20 | C7: 3 | D7: 석 | E7: =SUMIFS(전체내역!$J$5:$J$48,전체내역!$A$5:$A$48,"B2",전체내역!$D$5:$D$48,A7) -> 60 | F7: =E7*전체내역!$B$2 -> 93000 | G7: 좌석형 | H7: FE 2 + UX/UI 1
A8: Vercel Pro | B8: 20 | C8: 1 | D8: 개 | E8: =SUMIFS(전체내역!$J$5:$J$48,전체내역!$A$5:$A$48,"B2",전체내역!$D$5:$D$48,A8) -> 20 | F8: =E8*전체내역!$B$2 -> 31000 | G8: 팀별 인스턴스 | H8: 프론트 배포
A9: 고정구독 소계 | E9: =SUM(E6:E8) -> 200 | F9: =SUM(F6:F8) -> 310000
A10: 클라우드/배포
A11: AWS EC2 (후불) | B11: 18 | C11: 1 | D11: 개 | E11: =SUMIFS(전체내역!$J$5:$J$48,전체내역!$A$5:$A$48,"B2",전체내역!$D$5:$D$48,A11) -> 18 | F11: =E11*전체내역!$B$2 -> 27900 | G11: 팀별 인스턴스 | H11: 백엔드 배포
A12: 클라우드/배포 소계 | E12: =SUM(E11:E11) -> 18 | F12: =SUM(F11:F11) -> 27900
A13: LLM API
A14: claude-sonnet API | B14: 0.0255 | C14: 300 | D14: 호출 | E14: =SUMIFS(전체내역!$J$5:$J$48,전체내역!$A$5:$A$48,"B2",전체내역!$D$5:$D$48,A14) -> 7.65 | F14: =E14*전체내역!$B$2 -> 11857.5 | G14: API 키형 | H14: 영상 프롬프트 생성
A15: GPT-4.1 vision (상위) | B15: 0.00875 | C15: 1500 | D15: 호출 | E15: =SUMIFS(전체내역!$J$5:$J$48,전체내역!$A$5:$A$48,"B2",전체내역!$D$5:$D$48,A15) -> 13.125 | F15: =E15*전체내역!$B$2 -> 20343.75 | G15: API 키형 | H15: 컷 생성·이미지 분석
A16: LLM API 소계 | E16: =SUM(E14:E15) -> 20.775 | F16: =SUM(F14:F15) -> 32201.25
A17: 이미지 생성
A18: gemini-3.5-flash-image | B18: 0.039 | C18: 1500 | D18: 장 | E18: =SUMIFS(전체내역!$J$5:$J$48,전체내역!$A$5:$A$48,"B2",전체내역!$D$5:$D$48,A18) -> 58.5 | F18: =E18*전체내역!$B$2 -> 90675 | G18: API 키형 | H18: 이미지 생성
A19: 이미지 생성 소계 | E19: =SUM(E18:E18) -> 58.5 | F19: =SUM(F18:F18) -> 90675
A20: ★ 총 합계 | E20: =SUMIF(전체내역!$A$5:$A$48,"B2",전체내역!$J$5:$J$48) -> 297.275 | F20: =SUMIF(전체내역!$A$5:$A$48,"B2",전체내역!$K$5:$K$48) -> 460776.25

Sheet C
A1: KX_C · 1개월 예상 비용 (청구용)
A2: 환율 1,550 KRW/USD · 청구기간 1개월 · 금액은 전체내역 마스터와 연동
A4: 항목 | B4: 단가(USD) | C4: 수량 | D4: 단위 | E4: 합계(USD) | F4: 합계(KRW) | G4: 조달유형 | H4: 용도·목적
A5: 고정구독
A6: Claude Team | B6: 30 | C6: 4 | D6: 석 | E6: =SUMIFS(전체내역!$J$5:$J$48,전체내역!$A$5:$A$48,"C",전체내역!$D$5:$D$48,A6) -> 120 | F6: =E6*전체내역!$B$2 -> 186000 | G6: 좌석형 | H6: 백엔드 코드 생성·API 연동 AI 지원 (Team 통일)
A7: Figma Professional | B7: 20 | C7: 3 | D7: 석 | E7: =SUMIFS(전체내역!$J$5:$J$48,전체내역!$A$5:$A$48,"C",전체내역!$D$5:$D$48,A7) -> 60 | F7: =E7*전체내역!$B$2 -> 93000 | G7: 좌석형 | H7: PM 1 + FE 1 + UX/UI 1, 화면 설계·협업
A8: Vercel Pro | B8: 20 | C8: 1 | D8: 개 | E8: =SUMIFS(전체내역!$J$5:$J$48,전체내역!$A$5:$A$48,"C",전체내역!$D$5:$D$48,A8) -> 20 | F8: =E8*전체내역!$B$2 -> 31000 | G8: 팀별 인스턴스 | H8: Next.js 프론트 배포·데모 운영
A9: ElevenLabs | B9: 6 | C9: 1 | D9: 개 | E9: =SUMIFS(전체내역!$J$5:$J$48,전체내역!$A$5:$A$48,"C",전체내역!$D$5:$D$48,A9) -> 6 | F9: =E9*전체내역!$B$2 -> 9300 | G9: 좌석형(키 공유) | H9: 효과음 생성 API (키 공유)
A10: 고정구독 소계 | E10: =SUM(E6:E9) -> 206 | F10: =SUM(F6:F9) -> 319300
A11: 클라우드/배포
A12: AWS EC2 (t3.small, 후불) | B12: 20 | C12: 1 | D12: 개 | E12: =SUMIFS(전체내역!$J$5:$J$48,전체내역!$A$5:$A$48,"C",전체내역!$D$5:$D$48,A12) -> 20 | F12: =E12*전체내역!$B$2 -> 31000 | G12: 팀별 인스턴스 | H12: Spring Boot 백엔드 서버 운영
A13: 클라우드/배포 소계 | E13: =SUM(E12:E12) -> 20 | F13: =SUM(F12:F12) -> 31000
A14: STT/자막
A15: OpenAI Whisper API | B15: 0.03 | C15: 300 | D15: 호출 | E15: =SUMIFS(전체내역!$J$5:$J$48,전체내역!$A$5:$A$48,"C",전체내역!$D$5:$D$48,A15) -> 9 | F15: =E15*전체내역!$B$2 -> 13950 | G15: API 키형 | H15: STT·자동 자막 (성능 비교)
A16: AssemblyAI | B16: 0.0175 | C16: 300 | D16: 호출 | E16: =SUMIFS(전체내역!$J$5:$J$48,전체내역!$A$5:$A$48,"C",전체내역!$D$5:$D$48,A16) -> 5.25 | F16: =E16*전체내역!$B$2 -> 8137.5 | G16: API 키형 | H16: 정밀 자막·타임스탬프 변환
A17: STT/자막 소계 | E17: =SUM(E15:E16) -> 14.25 | F17: =SUM(F15:F16) -> 22087.5
A18: ★ 총 합계 | E18: =SUMIF(전체내역!$A$5:$A$48,"C",전체내역!$J$5:$J$48) -> 240.25 | F18: =SUMIF(전체내역!$A$5:$A$48,"C",전체내역!$K$5:$K$48) -> 372387.5
